[2021-04-09 14:56:30,117] [INFO] [base._start_message] -> 
                 --------------------------------------------------
                 Starting fuzzing session
                 Target: TcpTarget
                 UI: EmptyInterface
                 Log: ./kittylogs/kitty_20210409-145629.log

                 Total possible mutation count: 2
                 --------------------------------------------------
                                 Happy hacking
                 --------------------------------------------------
            
[2021-04-09 14:56:30,123] [INFO] [ics_fuzzer.start] -> Skipping environment test
[2021-04-09 14:56:30,134] [INFO] [ics_fuzzer._start] -> should keep running? True
[2021-04-09 14:56:30,478] [INFO] [tcp.pre_test] -> host>>>>10.151.197.241
[2021-04-09 14:56:30,481] [INFO] [tcp.pre_test] -> port>>>>102
[2021-04-09 14:56:30,535] [ERROR] [tcp.pre_test] -> Error: Traceback (most recent call last):
  File "/home/uzio/APPs/Fuzz-master/katnip/targets/tcp.py", line 61, in pre_test
    sock.connect((self.host, self.port))
  File "/usr/lib/python2.7/socket.py", line 228, in meth
    return getattr(self._sock,name)(*args)
error: [Errno 111] Connection refused

[2021-04-09 14:56:30,536] [ERROR] [tcp.pre_test] -> Failed to connect to target server, retrying...
